Workbook
Name ServiceLevel: Assumptions!$B$5
Name z: Assumptions!$B$6
Name OrderCost: Assumptions!$B$7
Name HoldRate: Assumptions!$B$8
Name WeeksYear: Assumptions!$B$9
Name CurrentCoverWks: Assumptions!$B$10
Name LastWeek: Assumptions!$B$11
Name ACut: Assumptions!$B$13
Name BCut: Assumptions!$B$14
Name XMaxCV: Assumptions!$B$15
Name YMaxCV: Assumptions!$B$16
Name wLate: Assumptions!$B$18
Name wLTV: Assumptions!$B$19
Name wQuality: Assumptions!$B$20
Name wCountry: Assumptions!$B$21
Name wSpend: Assumptions!$B$22
Name BadLate: Assumptions!$B$25
Name BadLTV: Assumptions!$B$26
Name BadQuality: Assumptions!$B$27
Name BadSpend: Assumptions!$B$28
Name Markup: Assumptions!$B$30
Name CountryList: Assumptions!$A$33:$A$40
Name CountryScore: Assumptions!$B$33:$B$40
Name DriverList: Assumptions!$A$43:$A$47
Name DriverAction: Assumptions!$C$43:$C$47
Name SegList: Assumptions!$A$50:$A$58
Name SegStrategy: Assumptions!$C$50:$C$58
Name D_Week: Weekly_Demand!$A$2:$A$5097
Name D_SKU: Weekly_Demand!$B$2:$B$5097
Name D_Units: Weekly_Demand!$C$2:$C$5097
Name D_Last52: Weekly_Demand!$D$2:$D$5097
Name D_Units2: Weekly_Demand!$E$2:$E$5097
Name PO_Sup: Purchase_Orders!$B$2:$B$1275
Name PO_SKU: Purchase_Orders!$C$2:$C$1275
Name PO_QtyOrd: Purchase_Orders!$G$2:$G$1275
Name PO_QtyRec: Purchase_Orders!$H$2:$H$1275
Name PO_QtyDef: Purchase_Orders!$I$2:$I$1275
Name PO_Value: Purchase_Orders!$J$2:$J$1275
Name PO_LT: Purchase_Orders!$K$2:$K$1275
Name PO_LT2: Purchase_Orders!$L$2:$L$1275
Name PO_OnTime: Purchase_Orders!$M$2:$M$1275
Name PO_DaysLate: Purchase_Orders!$N$2:$N$1275
Name SC_ID: Supplier_Scorecard!$A$5:$A$12
Name SC_LT: Supplier_Scorecard!$I$5:$I$12
Name SC_LTStd: Supplier_Scorecard!$J$5:$J$12
Name P_SKU: Inventory_Policy!$A$5:$A$53
Name P_Name: Inventory_Policy!$B$5:$B$53
Name P_Sup: Inventory_Policy!$D$5:$D$53
Name P_Cost: Inventory_Policy!$E$5:$E$53
Name P_Spend: Inventory_Policy!$I$5:$I$53
Name P_ABC: Inventory_Policy!$K$5:$K$53
Name P_XYZ: Inventory_Policy!$M$5:$M$53
Name P_Seg: Inventory_Policy!$N$5:$N$53
Name P_LT: Inventory_Policy!$O$5:$O$53
Name P_SS: Inventory_Policy!$Q$5:$Q$53
Name P_ROP: Inventory_Policy!$R$5:$R$53
Name P_EOQ: Inventory_Policy!$S$5:$S$53
Name P_OnHand: Inventory_Policy!$T$5:$T$53
Name P_OnOrder: Inventory_Policy!$U$5:$U$53
Name P_Pos: Inventory_Policy!$V$5:$V$53

Sheet README
A1: Supply Chain Inventory Optimization & Supplier Risk Analytics (Excel model)
A2: Every result is a live Excel formula. Built by Dhruvilkumar Upadhyay.
A4: How to use
A5: 1. Assumptions | B5: Change any blue-on-yellow cell (service level, ordering cost, risk weights...). The whole model recalculates.
A6: 2. Dashboard | B6: KPIs, inventory status, supplier risk chart, ABC-XYZ matrix and the 'what to order today' list.
A7: 3. Inventory_Policy | B7: One row per SKU: ABC-XYZ class, safety stock, reorder point, EOQ, status and suggested order quantity.
A8: 4. Supplier_Scorecard | B8: On-time delivery, lead time, defects, spend share and a weighted 0-100 risk score with a recommended action.
A9: 5. Forecast | B9: Pick a SKU from the dropdown in B4 to back-test 3 forecasting methods and see a 12-week forecast.
A10: 6. Disruption_Simulator | B10: Pick a supplier (B4) and an extra delay (B5) to see which SKUs stock out and the revenue at risk.
A11: 7. Landed_Cost | B11: Offshore vs nearshore: total landed cost (price, freight, duty, brokerage, plus the cost of safety stock and in-transit inventory) for every SKU bought overseas.
A12: Data sheets | B12: Products, Suppliers, Weekly_Demand, Purchase_Orders, Inventory. Replace them with your own data (same columns).
A13: Colour code | B13: Blue text = input you can change. Green text = link to another sheet. Black = formula.
A14: Key formulas
A15: Safety stock | B15: z x SQRT( lead time x demand std² + avg demand² x lead time std² )
A16: Reorder point | B16: avg weekly demand x lead time + safety stock
A17: EOQ | B17: SQRT( 2 x annual demand x ordering cost / (unit cost x holding rate) )
A18: WAPE | B18: SUM(|actual - forecast|) / SUM(actual)
A19: Data source | B19: NorthBridge is a fictional company. The data is simulated because real supply chain data is confidential. The analysis is built to run the same way on a real ERP export.
A20: Python version | B20: The same analysis is automated in Python (src/main.py). That version uses forecast error for safety stock, so numbers differ slightly.

Sheet Dashboard
A1: Supply Chain Control Tower
A2: Inventory optimization, demand forecasting and supplier risk. All figures are live formulas; change inputs on the Assumptions sheet.
B4: Annual spend analysed | E4: Spend in A-class SKUs | H4: SKUs to order now | K4: EOQ saving per year
B5: =SUM(P_Spend) | E5: =SUMIF(P_ABC,"A",P_Spend)/SUM(P_Spend) | H5: =COUNTIF(P_Status,"Order now")+COUNTIF(P_Status,"Critical - expedite") | K5: =SUM(P_Saving)
B6: =COUNTA(P_SKU)&" SKUs, "&COUNTA(SC_ID)&" suppliers" | E6: ="from "&COUNTIF(P_ABC,"A")&" SKUs ("&TEXT(COUNTIF(P_ABC,"A")/COUNTA(P_SKU),"0%")&")" | H6: =COUNTIF(P_Status,"Critical - expedite")&" critical (below safety stock)" | K6: =TEXT(SUM(P_Saving)/SUM(P_CurCost),"0.0%")&" lower ordering + holding cost"
B8: Excess inventory | E8: Safety stock investment | H8: Supplier on-time delivery | K8: High-risk suppliers
B9: =SUM(P_Excess) | E9: =SUM(P_SSValue) | H9: =AVERAGE(PO_OnTime) | K9: =COUNTIF(Supplier_Scorecard!$Z$5:$Z$12,"High")
B10: =COUNTIF(P_Status,"Overstock")&" SKUs above max stock" | E10: ="at "&TEXT(ServiceLevel,"0%")&" service level" | H10: =COUNTA(PO_OnTime)&" purchase orders" | K10: ="Top: "&INDEX(Supplier_Scorecard!$B$5:$B$12,MATCH(1,Supplier_Scorecard!$AC$5:$AC$12,0))
B12: Inventory status | M12: ABC-XYZ matrix (SKU count)
B13: Critical - expedite | C13: =COUNTIF(P_Status,B13) | N13: X stable | O13: Y variable | P13: Z erratic
B14: Order now | C14: =COUNTIF(P_Status,B14) | M14: A | N14: =COUNTIFS(P_ABC,"A",P_XYZ,"X") | O14: =COUNTIFS(P_ABC,"A",P_XYZ,"Y") | P14: =COUNTIFS(P_ABC,"A",P_XYZ,"Z")
B15: Healthy | C15: =COUNTIF(P_Status,B15) | M15: B | N15: =COUNTIFS(P_ABC,"B",P_XYZ,"X") | O15: =COUNTIFS(P_ABC,"B",P_XYZ,"Y") | P15: =COUNTIFS(P_ABC,"B",P_XYZ,"Z")
B16: Overstock | C16: =COUNTIF(P_Status,B16) | M16: C | N16: =COUNTIFS(P_ABC,"C",P_XYZ,"X") | O16: =COUNTIFS(P_ABC,"C",P_XYZ,"Y") | P16: =COUNTIFS(P_ABC,"C",P_XYZ,"Z")
B33: What to order today
B34: Product | C34: SKU | E34: Status | F34: Position | H34: Reorder point | I34: Order qty | K34: Supplier
B35: =IF($R35="","",INDEX(P_Name,$R35)) | C35: =IF($R35="","",INDEX(P_SKU,$R35)) | E35: =IF($R35="","",INDEX(P_Status,$R35)) | F35: =IF($R35="","",INDEX(P_Pos,$R35)) | H35: =IF($R35="","",INDEX(P_ROP,$R35)) | I35: =IF($R35="","",INDEX(P_Order,$R35)) | K35: =IF($R35="","",INDEX(P_Sup,$R35)) | R35: =IFERROR(MATCH(1,P_ActRow,0),"")
B36: =IF($R36="","",INDEX(P_Name,$R36)) | C36: =IF($R36="","",INDEX(P_SKU,$R36)) | E36: =IF($R36="","",INDEX(P_Status,$R36)) | F36: =IF($R36="","",INDEX(P_Pos,$R36)) | H36: =IF($R36="","",INDEX(P_ROP,$R36)) | I36: =IF($R36="","",INDEX(P_Order,$R36)) | K36: =IF($R36="","",INDEX(P_Sup,$R36)) | R36: =IFERROR(MATCH(2,P_ActRow,0),"")
B37: =IF($R37="","",INDEX(P_Name,$R37)) | C37: =IF($R37="","",INDEX(P_SKU,$R37)) | E37: =IF($R37="","",INDEX(P_Status,$R37)) | F37: =IF($R37="","",INDEX(P_Pos,$R37)) | H37: =IF($R37="","",INDEX(P_ROP,$R37)) | I37: =IF($R37="","",INDEX(P_Order,$R37)) | K37: =IF($R37="","",INDEX(P_Sup,$R37)) | R37: =IFERROR(MATCH(3,P_ActRow,0),"")
B38: =IF($R38="","",INDEX(P_Name,$R38)) | C38: =IF($R38="","",INDEX(P_SKU,$R38)) | E38: =IF($R38="","",INDEX(P_Status,$R38)) | F38: =IF($R38="","",INDEX(P_Pos,$R38)) | H38: =IF($R38="","",INDEX(P_ROP,$R38)) | I38: =IF($R38="","",INDEX(P_Order,$R38)) | K38: =IF($R38="","",INDEX(P_Sup,$R38)) | R38: =IFERROR(MATCH(4,P_ActRow,0),"")
B39: =IF($R39="","",INDEX(P_Name,$R39)) | C39: =IF($R39="","",INDEX(P_SKU,$R39)) | E39: =IF($R39="","",INDEX(P_Status,$R39)) | F39: =IF($R39="","",INDEX(P_Pos,$R39)) | H39: =IF($R39="","",INDEX(P_ROP,$R39)) | I39: =IF($R39="","",INDEX(P_Order,$R39)) | K39: =IF($R39="","",INDEX(P_Sup,$R39)) | R39: =IFERROR(MATCH(5,P_ActRow,0),"")
B40: =IF($R40="","",INDEX(P_Name,$R40)) | C40: =IF($R40="","",INDEX(P_SKU,$R40)) | E40: =IF($R40="","",INDEX(P_Status,$R40)) | F40: =IF($R40="","",INDEX(P_Pos,$R40)) | H40: =IF($R40="","",INDEX(P_ROP,$R40)) | I40: =IF($R40="","",INDEX(P_Order,$R40)) | K40: =IF($R40="","",INDEX(P_Sup,$R40)) | R40: =IFERROR(MATCH(6,P_ActRow,0),"")
B41: =IF($R41="","",INDEX(P_Name,$R41)) | C41: =IF($R41="","",INDEX(P_SKU,$R41)) | E41: =IF($R41="","",INDEX(P_Status,$R41)) | F41: =IF($R41="","",INDEX(P_Pos,$R41)) | H41: =IF($R41="","",INDEX(P_ROP,$R41)) | I41: =IF($R41="","",INDEX(P_Order,$R41)) | K41: =IF($R41="","",INDEX(P_Sup,$R41)) | R41: =IFERROR(MATCH(7,P_ActRow,0),"")
B42: =IF($R42="","",INDEX(P_Name,$R42)) | C42: =IF($R42="","",INDEX(P_SKU,$R42)) | E42: =IF($R42="","",INDEX(P_Status,$R42)) | F42: =IF($R42="","",INDEX(P_Pos,$R42)) | H42: =IF($R42="","",INDEX(P_ROP,$R42)) | I42: =IF($R42="","",INDEX(P_Order,$R42)) | K42: =IF($R42="","",INDEX(P_Sup,$R42)) | R42: =IFERROR(MATCH(8,P_ActRow,0),"")
B43: =IF($R43="","",INDEX(P_Name,$R43)) | C43: =IF($R43="","",INDEX(P_SKU,$R43)) | E43: =IF($R43="","",INDEX(P_Status,$R43)) | F43: =IF($R43="","",INDEX(P_Pos,$R43)) | H43: =IF($R43="","",INDEX(P_ROP,$R43)) | I43: =IF($R43="","",INDEX(P_Order,$R43)) | K43: =IF($R43="","",INDEX(P_Sup,$R43)) | R43: =IFERROR(MATCH(9,P_ActRow,0),"")
B44: =IF($R44="","",INDEX(P_Name,$R44)) | C44: =IF($R44="","",INDEX(P_SKU,$R44)) | E44: =IF($R44="","",INDEX(P_Status,$R44)) | F44: =IF($R44="","",INDEX(P_Pos,$R44)) | H44: =IF($R44="","",INDEX(P_ROP,$R44)) | I44: =IF($R44="","",INDEX(P_Order,$R44)) | K44: =IF($R44="","",INDEX(P_Sup,$R44)) | R44: =IFERROR(MATCH(10,P_ActRow,0),"")
B45: =IF($R45="","",INDEX(P_Name,$R45)) | C45: =IF($R45="","",INDEX(P_SKU,$R45)) | E45: =IF($R45="","",INDEX(P_Status,$R45)) | F45: =IF($R45="","",INDEX(P_Pos,$R45)) | H45: =IF($R45="","",INDEX(P_ROP,$R45)) | I45: =IF($R45="","",INDEX(P_Order,$R45)) | K45: =IF($R45="","",INDEX(P_Sup,$R45)) | R45: =IFERROR(MATCH(11,P_ActRow,0),"")
B46: =IF($R46="","",INDEX(P_Name,$R46)) | C46: =IF($R46="","",INDEX(P_SKU,$R46)) | E46: =IF($R46="","",INDEX(P_Status,$R46)) | F46: =IF($R46="","",INDEX(P_Pos,$R46)) | H46: =IF($R46="","",INDEX(P_ROP,$R46)) | I46: =IF($R46="","",INDEX(P_Order,$R46)) | K46: =IF($R46="","",INDEX(P_Sup,$R46)) | R46: =IFERROR(MATCH(12,P_ActRow,0),"")
B47: =IF($R47="","",INDEX(P_Name,$R47)) | C47: =IF($R47="","",INDEX(P_SKU,$R47)) | E47: =IF($R47="","",INDEX(P_Status,$R47)) | F47: =IF($R47="","",INDEX(P_Pos,$R47)) | H47: =IF($R47="","",INDEX(P_ROP,$R47)) | I47: =IF($R47="","",INDEX(P_Order,$R47)) | K47: =IF($R47="","",INDEX(P_Sup,$R47)) | R47: =IFERROR(MATCH(13,P_ActRow,0),"")
B48: =IF($R48="","",INDEX(P_Name,$R48)) | C48: =IF($R48="","",INDEX(P_SKU,$R48)) | E48: =IF($R48="","",INDEX(P_Status,$R48)) | F48: =IF($R48="","",INDEX(P_Pos,$R48)) | H48: =IF($R48="","",INDEX(P_ROP,$R48)) | I48: =IF($R48="","",INDEX(P_Order,$R48)) | K48: =IF($R48="","",INDEX(P_Sup,$R48)) | R48: =IFERROR(MATCH(14,P_ActRow,0),"")
B49: =IF($R49="","",INDEX(P_Name,$R49)) | C49: =IF($R49="","",INDEX(P_SKU,$R49)) | E49: =IF($R49="","",INDEX(P_Status,$R49)) | F49: =IF($R49="","",INDEX(P_Pos,$R49)) | H49: =IF($R49="","",INDEX(P_ROP,$R49)) | I49: =IF($R49="","",INDEX(P_Order,$R49)) | K49: =IF($R49="","",INDEX(P_Sup,$R49)) | R49: =IFERROR(MATCH(15,P_ActRow,0),"")
B50: =IF($R50="","",INDEX(P_Name,$R50)) | C50: =IF($R50="","",INDEX(P_SKU,$R50)) | E50: =IF($R50="","",INDEX(P_Status,$R50)) | F50: =IF($R50="","",INDEX(P_Pos,$R50)) | H50: =IF($R50="","",INDEX(P_ROP,$R50)) | I50: =IF($R50="","",INDEX(P_Order,$R50)) | K50: =IF($R50="","",INDEX(P_Sup,$R50)) | R50: =IFERROR(MATCH(16,P_ActRow,0),"")
B51: =IF($R51="","",INDEX(P_Name,$R51)) | C51: =IF($R51="","",INDEX(P_SKU,$R51)) | E51: =IF($R51="","",INDEX(P_Status,$R51)) | F51: =IF($R51="","",INDEX(P_Pos,$R51)) | H51: =IF($R51="","",INDEX(P_ROP,$R51)) | I51: =IF($R51="","",INDEX(P_Order,$R51)) | K51: =IF($R51="","",INDEX(P_Sup,$R51)) | R51: =IFERROR(MATCH(17,P_ActRow,0),"")
B52: =IF($R52="","",INDEX(P_Name,$R52)) | C52: =IF($R52="","",INDEX(P_SKU,$R52)) | E52: =IF($R52="","",INDEX(P_Status,$R52)) | F52: =IF($R52="","",INDEX(P_Pos,$R52)) | H52: =IF($R52="","",INDEX(P_ROP,$R52)) | I52: =IF($R52="","",INDEX(P_Order,$R52)) | K52: =IF($R52="","",INDEX(P_Sup,$R52)) | R52: =IFERROR(MATCH(18,P_ActRow,0),"")
B53: =IF($R53="","",INDEX(P_Name,$R53)) | C53: =IF($R53="","",INDEX(P_SKU,$R53)) | E53: =IF($R53="","",INDEX(P_Status,$R53)) | F53: =IF($R53="","",INDEX(P_Pos,$R53)) | H53: =IF($R53="","",INDEX(P_ROP,$R53)) | I53: =IF($R53="","",INDEX(P_Order,$R53)) | K53: =IF($R53="","",INDEX(P_Sup,$R53)) | R53: =IFERROR(MATCH(19,P_ActRow,0),"")
B54: =IF($R54="","",INDEX(P_Name,$R54)) | C54: =IF($R54="","",INDEX(P_SKU,$R54)) | E54: =IF($R54="","",INDEX(P_Status,$R54)) | F54: =IF($R54="","",INDEX(P_Pos,$R54)) | H54: =IF($R54="","",INDEX(P_ROP,$R54)) | I54: =IF($R54="","",INDEX(P_Order,$R54)) | K54: =IF($R54="","",INDEX(P_Sup,$R54)) | R54: =IFERROR(MATCH(20,P_ActRow,0),"")
B55: =IF(COUNT(P_ActRow)>20,"+ "&(COUNT(P_ActRow)-20)&" more on the Inventory_Policy sheet","")

Sheet Assumptions
A1: Assumptions
A2: Blue text on yellow = inputs you can change. Everything else in the workbook recalculates.
A4: Inventory policy
A5: Service level | B5: 0.95 | C5: Target share of order cycles with no stockout
A6: z-score | B6: =NORMSINV(ServiceLevel) | C6: Calculated from the service level (95% -> 1.645)
A7: Ordering cost per PO (CAD) | B7: 85 | C7: Admin, freight booking, receiving. Assumption
A8: Annual holding cost rate | B8: 0.22 | C8: Capital, storage, insurance, obsolescence. Assumption
A9: Weeks per year | B9: 52
A10: Current ordering habit (weeks of demand per PO) | B10: 4 | C10: Used to compare today's ordering with EOQ
A11: Last week in data | B11: =MAX(Weekly_Demand!$A$2:$A$5097) | C11: Analysis uses the 52 weeks up to this date
A12: Classification
A13: ABC: A-class cut-off (cumulative spend) | B13: 0.8 | C13: First 80% of spend = A
A14: ABC: B-class cut-off | B14: 0.95 | C14: Next 15% = B, rest = C
A15: XYZ: X max coefficient of variation | B15: 0.25 | C15: Stable demand
A16: XYZ: Y max coefficient of variation | B16: 0.5 | C16: Variable demand; above = Z (erratic)
A17: Supplier risk weights (must total 100%)
A18: Weight: late delivery | B18: 0.3
A19: Weight: lead-time variability | B19: 0.2
A20: Weight: quality (defects) | B20: 0.2
A21: Weight: country / route risk | B21: 0.15
A22: Weight: spend dependency | B22: 0.15
A23: Check: weights total | B23: =wLate+wLTV+wQuality+wCountry+wSpend | C23: Should be 100%
A24: 'Clearly bad' thresholds (factor score = 1)
A25: Late-delivery rate | B25: 0.35 | C25: 35% of POs late
A26: Lead-time coefficient of variation | B26: 0.3
A27: Defect rate | B27: 0.025 | C27: 2.5% of units defective
A28: Share of total spend with one supplier | B28: 0.3
A29: Disruption simulator
A30: Selling price markup on cost | B30: 1.35 | C30: Used to turn units short into revenue at risk. Assumption
A32: Country / route risk (1 = low, 5 = high)
A33: Canada | B33: 1 | C33: Illustrative assumptions (distance, port congestion, tariffs, geopolitics), not official ratings
A34: USA | B34: 2
A35: Germany | B35: 2
A36: Mexico | B36: 3
A37: Malaysia | B37: 3
A38: India | B38: 4
A39: Vietnam | B39: 4
A40: China | B40: 5
A42: Recommended action by main risk driver
A43: late delivery | C43: Quarterly business review with OTD target; add late-delivery clause to contract
...

Sheet Inventory_Policy
A1: Inventory Policy: ABC-XYZ, Safety Stock, Reorder Point, EOQ
A2: One row per SKU. Demand statistics use the last 52 weeks. Status compares inventory position (on hand + on order) with safety stock and reorder point.
A4: SKU | B4: Product | C4: Category | D4: Supplier ID | E4: Unit cost (CAD) | F4: Annual units (52w) | G4: Avg weekly demand | H4: Weekly demand std | I4: Annual spend (CAD) | J4: Cum. spend share before SKU | K4: ABC | L4: Demand CV | M4: XYZ | N4: Segment | O4: Lead time (wks) | P4: Lead time std (wks) | Q4: Safety stock | R4: Reorder point | S4: EOQ | T4: On hand | U4: On order | V4: Inventory position | W4: Weeks of cover | X4: Status | Y4: Suggested order qty | Z4: Excess value (CAD) | AA4: Safety stock value (CAD) | AB4: Current ordering cost/yr | AC4: EOQ ordering cost/yr | AD4: Annual saving (CAD) | AE4: Strategy | AF4: helper: simulator row | AG4: helper: action row
A5: =Products!A2 | B5: =Products!B2 | C5: =Products!C2 | D5: =Products!E2 | E5: =Products!D2 | F5: =SUMIFS(D_Units,D_SKU,A5,D_Last52,1) | G5: =IFERROR(AVERAGEIFS(D_Units,D_SKU,A5,D_Last52,1),0) | H5: =IFERROR(SQRT(MAX(0,(SUMIFS(D_Units2,D_SKU,A5)-COUNTIFS(D_SKU,A5,D_Last52,1)*G5^2)/(COUNTIFS(D_SKU,A5,D_Last52,1)-1))),0) | I5: =F5*E5 | J5: =IFERROR(SUMIF($I$5:$I$53,">"&I5)/SUM($I$5:$I$53),0) | K5: =IF(J5<ACut,"A",IF(J5<BCut,"B","C")) | L5: =IFERROR(H5/G5,0) | M5: =IF(L5<=XMaxCV,"X",IF(L5<=YMaxCV,"Y","Z")) | N5: =K5&M5 | O5: =IFERROR(INDEX(SC_LT,MATCH(D5,SC_ID,0)),0) | P5: =IFERROR(INDEX(SC_LTStd,MATCH(D5,SC_ID,0)),0) | Q5: =ROUNDUP(z*SQRT(O5*H5^2+G5^2*P5^2),0) | R5: =ROUNDUP(G5*O5+Q5,0) | S5: =IFERROR(ROUNDUP(SQRT(2*G5*WeeksYear*OrderCost/(E5*HoldRate)),0),0) | T5: =IFERROR(INDEX(Inventory!$B:$B,MATCH(A5,Inventory!$A:$A,0)),0) | U5: =IFERROR(INDEX(Inventory!$C:$C,MATCH(A5,Inventory!$A:$A,0)),0) | V5: =T5+U5 | W5: =IFERROR(T5/G5,0) | X5: =IF(V5<Q5,"Critical - expedite",IF(V5<=R5,"Order now",IF(V5>R5+S5,"Overstock","Healthy"))) | Y5: =IF(OR(X5="Critical - expedite",X5="Order now"),MAX(S5,R5+S5-V5),0) | Z5: =IF(X5="Overstock",(V5-R5-S5)*E5,0) | AA5: =Q5*E5 | AB5: =IFERROR(G5*WeeksYear/(G5*CurrentCoverWks)*OrderCost+G5*CurrentCoverWks/2*E5*HoldRate,0) | AC5: =IFERROR(G5*WeeksYear/S5*OrderCost+S5/2*E5*HoldRate,0) | AD5: =AB5-AC5 | AE5: =IFERROR(INDEX(SegStrategy,MATCH(N5,SegList,0)),"") | AF5: =IF(D5=SimSupplier,COUNTIF($D$5:D5,SimSupplier),"") | AG5: =IF(OR(X5="Critical - expedite",X5="Order now"),COUNTIF($X$5:X5,"Critical - expedite")+COUNTIF($X$5:X5,"Order now"),"")
A6: =Products!A3 | B6: =Products!B3 | C6: =Products!C3 | D6: =Products!E3 | E6: =Products!D3 | F6: =SUMIFS(D_Units,D_SKU,A6,D_Last52,1) | G6: =IFERROR(AVERAGEIFS(D_Units,D_SKU,A6,D_Last52,1),0) | H6: =IFERROR(SQRT(MAX(0,(SUMIFS(D_Units2,D_SKU,A6)-COUNTIFS(D_SKU,A6,D_Last52,1)*G6^2)/(COUNTIFS(D_SKU,A6,D_Last52,1)-1))),0) | I6: =F6*E6 | J6: =IFERROR(SUMIF($I$5:$I$53,">"&I6)/SUM($I$5:$I$53),0) | K6: =IF(J6<ACut,"A",IF(J6<BCut,"B","C")) | L6: =IFERROR(H6/G6,0) | M6: =IF(L6<=XMaxCV,"X",IF(L6<=YMaxCV,"Y","Z")) | N6: =K6&M6 | O6: =IFERROR(INDEX(SC_LT,MATCH(D6,SC_ID,0)),0) | P6: =IFERROR(INDEX(SC_LTStd,MATCH(D6,SC_ID,0)),0) | Q6: =ROUNDUP(z*SQRT(O6*H6^2+G6^2*P6^2),0) | R6: =ROUNDUP(G6*O6+Q6,0) | S6: =IFERROR(ROUNDUP(SQRT(2*G6*WeeksYear*OrderCost/(E6*HoldRate)),0),0) | T6: =IFERROR(INDEX(Inventory!$B:$B,MATCH(A6,Inventory!$A:$A,0)),0) | U6: =IFERROR(INDEX(Inventory!$C:$C,MATCH(A6,Inventory!$A:$A,0)),0) | V6: =T6+U6 | W6: =IFERROR(T6/G6,0) | X6: =IF(V6<Q6,"Critical - expedite",IF(V6<=R6,"Order now",IF(V6>R6+S6,"Overstock","Healthy"))) | Y6: =IF(OR(X6="Critical - expedite",X6="Order now"),MAX(S6,R6+S6-V6),0) | Z6: =IF(X6="Overstock",(V6-R6-S6)*E6,0) | AA6: =Q6*E6 | AB6: =IFERROR(G6*WeeksYear/(G6*CurrentCoverWks)*OrderCost+G6*CurrentCoverWks/2*E6*HoldRate,0) | AC6: =IFERROR(G6*WeeksYear/S6*OrderCost+S6/2*E6*HoldRate,0) | AD6: =AB6-AC6 | AE6: =IFERROR(INDEX(SegStrategy,MATCH(N6,SegList,0)),"") | AF6: =IF(D6=SimSupplier,COUNTIF($D$5:D6,SimSupplier),"") | AG6: =IF(OR(X6="Critical - expedite",X6="Order now"),COUNTIF($X$5:X6,"Critical - expedite")+COUNTIF($X$5:X6,"Order now"),"")
A7: =Products!A4 | B7: =Products!B4 | C7: =Products!C4 | D7: =Products!E4 | E7: =Products!D4 | F7: =SUMIFS(D_Units,D_SKU,A7,D_Last52,1) | G7: =IFERROR(AVERAGEIFS(D_Units,D_SKU,A7,D_Last52,1),0) | H7: =IFERROR(SQRT(MAX(0,(SUMIFS(D_Units2,D_SKU,A7)-COUNTIFS(D_SKU,A7,D_Last52,1)*G7^2)/(COUNTIFS(D_SKU,A7,D_Last52,1)-1))),0) | I7: =F7*E7 | J7: =IFERROR(SUMIF($I$5:$I$53,">"&I7)/SUM($I$5:$I$53),0) | K7: =IF(J7<ACut,"A",IF(J7<BCut,"B","C")) | L7: =IFERROR(H7/G7,0) | M7: =IF(L7<=XMaxCV,"X",IF(L7<=YMaxCV,"Y","Z")) | N7: =K7&M7 | O7: =IFERROR(INDEX(SC_LT,MATCH(D7,SC_ID,0)),0) | P7: =IFERROR(INDEX(SC_LTStd,MATCH(D7,SC_ID,0)),0) | Q7: =ROUNDUP(z*SQRT(O7*H7^2+G7^2*P7^2),0) | R7: =ROUNDUP(G7*O7+Q7,0) | S7: =IFERROR(ROUNDUP(SQRT(2*G7*WeeksYear*OrderCost/(E7*HoldRate)),0),0) | T7: =IFERROR(INDEX(Inventory!$B:$B,MATCH(A7,Inventory!$A:$A,0)),0) | U7: =IFERROR(INDEX(Inventory!$C:$C,MATCH(A7,Inventory!$A:$A,0)),0) | V7: =T7+U7 | W7: =IFERROR(T7/G7,0) | X7: =IF(V7<Q7,"Critical - expedite",IF(V7<=R7,"Order now",IF(V7>R7+S7,"Overstock","Healthy"))) | Y7: =IF(OR(X7="Critical - expedite",X7="Order now"),MAX(S7,R7+S7-V7),0) | Z7: =IF(X7="Overstock",(V7-R7-S7)*E7,0) | AA7: =Q7*E7 | AB7: =IFERROR(G7*WeeksYear/(G7*CurrentCoverWks)*OrderCost+G7*CurrentCoverWks/2*E7*HoldRate,0) | AC7: =IFERROR(G7*WeeksYear/S7*OrderCost+S7/2*E7*HoldRate,0) | AD7: =AB7-AC7 | AE7: =IFERROR(INDEX(SegStrategy,MATCH(N7,SegList,0)),"") | AF7: =IF(D7=SimSupplier,COUNTIF($D$5:D7,SimSupplier),"") | AG7: =IF(OR(X7="Critical - expedite",X7="Order now"),COUNTIF($X$5:X7,"Critical - expedite")+COUNTIF($X$5:X7,"Order now"),"")
A8: =Products!A5 | B8: =Products!B5 | C8: =Products!C5 | D8: =Products!E5 | E8: =Products!D5 | F8: =SUMIFS(D_Units,D_SKU,A8,D_Last52,1) | G8: =IFERROR(AVERAGEIFS(D_Units,D_SKU,A8,D_Last52,1),0) | H8: =IFERROR(SQRT(MAX(0,(SUMIFS(D_Units2,D_SKU,A8)-COUNTIFS(D_SKU,A8,D_Last52,1)*G8^2)/(COUNTIFS(D_SKU,A8,D_Last52,1)-1))),0) | I8: =F8*E8 | J8: =IFERROR(SUMIF($I$5:$I$53,">"&I8)/SUM($I$5:$I$53),0) | K8: =IF(J8<ACut,"A",IF(J8<BCut,"B","C")) | L8: =IFERROR(H8/G8,0) | M8: =IF(L8<=XMaxCV,"X",IF(L8<=YMaxCV,"Y","Z")) | N8: =K8&M8 | O8: =IFERROR(INDEX(SC_LT,MATCH(D8,SC_ID,0)),0) | P8: =IFERROR(INDEX(SC_LTStd,MATCH(D8,SC_ID,0)),0) | Q8: =ROUNDUP(z*SQRT(O8*H8^2+G8^2*P8^2),0) | R8: =ROUNDUP(G8*O8+Q8,0) | S8: =IFERROR(ROUNDUP(SQRT(2*G8*WeeksYear*OrderCost/(E8*HoldRate)),0),0) | T8: =IFERROR(INDEX(Inventory!$B:$B,MATCH(A8,Inventory!$A:$A,0)),0) | U8: =IFERROR(INDEX(Inventory!$C:$C,MATCH(A8,Inventory!$A:$A,0)),0) | V8: =T8+U8 | W8: =IFERROR(T8/G8,0) | X8: =IF(V8<Q8,"Critical - expedite",IF(V8<=R8,"Order now",IF(V8>R8+S8,"Overstock","Healthy"))) | Y8: =IF(OR(X8="Critical - expedite",X8="Order now"),MAX(S8,R8+S8-V8),0) | Z8: =IF(X8="Overstock",(V8-R8-S8)*E8,0) | AA8: =Q8*E8 | AB8: =IFERROR(G8*WeeksYear/(G8*CurrentCoverWks)*OrderCost+G8*CurrentCoverWks/2*E8*HoldRate,0) | AC8: =IFERROR(G8*WeeksYear/S8*OrderCost+S8/2*E8*HoldRate,0) | AD8: =AB8-AC8 | AE8: =IFERROR(INDEX(SegStrategy,MATCH(N8,SegList,0)),"") | AF8: =IF(D8=SimSupplier,COUNTIF($D$5:D8,SimSupplier),"") | AG8: =IF(OR(X8="Critical - expedite",X8="Order now"),COUNTIF($X$5:X8,"Critical - expedite")+COUNTIF($X$5:X8,"Order now"),"")
A9: =Products!A6 | B9: =Products!B6 | C9: =Products!C6 | D9: =Products!E6 | E9: =Products!D6 | F9: =SUMIFS(D_Units,D_SKU,A9,D_Last52,1) | G9: =IFERROR(AVERAGEIFS(D_Units,D_SKU,A9,D_Last52,1),0) | H9: =IFERROR(SQRT(MAX(0,(SUMIFS(D_Units2,D_SKU,A9)-COUNTIFS(D_SKU,A9,D_Last52,1)*G9^2)/(COUNTIFS(D_SKU,A9,D_Last52,1)-1))),0) | I9: =F9*E9 | J9: =IFERROR(SUMIF($I$5:$I$53,">"&I9)/SUM($I$5:$I$53),0) | K9: =IF(J9<ACut,"A",IF(J9<BCut,"B","C")) | L9: =IFERROR(H9/G9,0) | M9: =IF(L9<=XMaxCV,"X",IF(L9<=YMaxCV,"Y","Z")) | N9: =K9&M9 | O9: =IFERROR(INDEX(SC_LT,MATCH(D9,SC_ID,0)),0) | P9: =IFERROR(INDEX(SC_LTStd,MATCH(D9,SC_ID,0)),0) | Q9: =ROUNDUP(z*SQRT(O9*H9^2+G9^2*P9^2),0) | R9: =ROUNDUP(G9*O9+Q9,0) | S9: =IFERROR(ROUNDUP(SQRT(2*G9*WeeksYear*OrderCost/(E9*HoldRate)),0),0) | T9: =IFERROR(INDEX(Inventory!$B:$B,MATCH(A9,Inventory!$A:$A,0)),0) | U9: =IFERROR(INDEX(Inventory!$C:$C,MATCH(A9,Inventory!$A:$A,0)),0) | V9: =T9+U9 | W9: =IFERROR(T9/G9,0) | X9: =IF(V9<Q9,"Critical - expedite",IF(V9<=R9,"Order now",IF(V9>R9+S9,"Overstock","Healthy"))) | Y9: =IF(OR(X9="Critical - expedite",X9="Order now"),MAX(S9,R9+S9-V9),0) | Z9: =IF(X9="Overstock",(V9-R9-S9)*E9,0) | AA9: =Q9*E9 | AB9: =IFERROR(G9*WeeksYear/(G9*CurrentCoverWks)*OrderCost+G9*CurrentCoverWks/2*E9*HoldRate,0) | AC9: =IFERROR(G9*WeeksYear/S9*OrderCost+S9/2*E9*HoldRate,0) | AD9: =AB9-AC9 | AE9: =IFERROR(INDEX(SegStrategy,MATCH(N9,SegList,0)),"") | AF9: =IF(D9=SimSupplier,COUNTIF($D$5:D9,SimSupplier),"") | AG9: =IF(OR(X9="Critical - expedite",X9="Order now"),COUNTIF($X$5:X9,"Critical - expedite")+COUNTIF($X$5:X9,"Order now"),"")
A10: =Products!A7 | B10: =Products!B7 | C10: =Products!C7 | D10: =Products!E7 | E10: =Products!D7 | F10: =SUMIFS(D_Units,D_SKU,A10,D_Last52,1) | G10: =IFERROR(AVERAGEIFS(D_Units,D_SKU,A10,D_Last52,1),0) | H10: =IFERROR(SQRT(MAX(0,(SUMIFS(D_Units2,D_SKU,A10)-COUNTIFS(D_SKU,A10,D_Last52,1)*G10^2)/(COUNTIFS(D_SKU,A10,D_Last52,1)-1))),0) | I10: =F10*E10 | J10: =IFERROR(SUMIF($I$5:$I$53,">"&I10)/SUM($I$5:$I$53),0) | K10: =IF(J10<ACut,"A",IF(J10<BCut,"B","C")) | L10: =IFERROR(H10/G10,0) | M10: =IF(L10<=XMaxCV,"X",IF(L10<=YMaxCV,"Y","Z")) | N10: =K10&M10 | O10: =IFERROR(INDEX(SC_LT,MATCH(D10,SC_ID,0)),0) | P10: =IFERROR(INDEX(SC_LTStd,MATCH(D10,SC_ID,0)),0) | Q10: =ROUNDUP(z*SQRT(O10*H10^2+G10^2*P10^2),0) | R10: =ROUNDUP(G10*O10+Q10,0) | S10: =IFERROR(ROUNDUP(SQRT(2*G10*WeeksYear*OrderCost/(E10*HoldRate)),0),0) | T10: =IFERROR(INDEX(Inventory!$B:$B,MATCH(A10,Inventory!$A:$A,0)),0) | U10: =IFERROR(INDEX(Inventory!$C:$C,MATCH(A10,Inventory!$A:$A,0)),0) | V10: =T10+U10 | W10: =IFERROR(T10/G10,0) | X10: =IF(V10<Q10,"Critical - expedite",IF(V10<=R10,"Order now",IF(V10>R10+S10,"Overstock","Healthy"))) | Y10: =IF(OR(X10="Critical - expedite",X10="Order now"),MAX(S10,R10+S10-V10),0) | Z10: =IF(X10="Overstock",(V10-R10-S10)*E10,0) | AA10: =Q10*E10 | AB10: =IFERROR(G10*WeeksYear/(G10*CurrentCoverWks)*OrderCost+G10*CurrentCoverWks/2*E10*HoldRate,0) | AC10: =IFERROR(G10*WeeksYear/S10*OrderCost+S10/2*E10*HoldRate,0) | AD10: =AB10-AC10 | AE10: =IFERROR(INDEX(SegStrategy,MATCH(N10,SegList,0)),"") | AF10: =IF(D10=SimSupplier,COUNTIF($D$5:D10,SimSupplier),"") | AG10: =IF(OR(X10="Critical - expedite",X10="Order now"),COUNTIF($X$5:X10,"Critical - expedite")+COUNTIF($X$5:X10,"Order now"),"")
A11: =Products!A8 | B11: =Products!B8 | C11: =Products!C8 | D11: =Products!E8 | E11: =Products!D8 | F11: =SUMIFS(D_Units,D_SKU,A11,D_Last52,1) | G11: =IFERROR(AVERAGEIFS(D_Units,D_SKU,A11,D_Last52,1),0) | H11: =IFERROR(SQRT(MAX(0,(SUMIFS(D_Units2,D_SKU,A11)-COUNTIFS(D_SKU,A11,D_Last52,1)*G11^2)/(COUNTIFS(D_SKU,A11,D_Last52,1)-1))),0) | I11: =F11*E11 | J11: =IFERROR(SUMIF($I$5:$I$53,">"&I11)/SUM($I$5:$I$53),0) | K11: =IF(J11<ACut,"A",IF(J11<BCut,"B","C")) | L11: =IFERROR(H11/G11,0) | M11: =IF(L11<=XMaxCV,"X",IF(L11<=YMaxCV,"Y","Z")) | N11: =K11&M11 | O11: =IFERROR(INDEX(SC_LT,MATCH(D11,SC_ID,0)),0) | P11: =IFERROR(INDEX(SC_LTStd,MATCH(D11,SC_ID,0)),0) | Q11: =ROUNDUP(z*SQRT(O11*H11^2+G11^2*P11^2),0) | R11: =ROUNDUP(G11*O11+Q11,0) | S11: =IFERROR(ROUNDUP(SQRT(2*G11*WeeksYear*OrderCost/(E11*HoldRate)),0),0) | T11: =IFERROR(INDEX(Inventory!$B:$B,MATCH(A11,Inventory!$A:$A,0)),0) | U11: =IFERROR(INDEX(Inventory!$C:$C,MATCH(A11,Inventory!$A:$A,0)),0) | V11: =T11+U11 | W11: =IFERROR(T11/G11,0) | X11: =IF(V11<Q11,"Critical - expedite",IF(V11<=R11,"Order now",IF(V11>R11+S11,"Overstock","Healthy"))) | Y11: =IF(OR(X11="Critical - expedite",X11="Order now"),MAX(S11,R11+S11-V11),0) | Z11: =IF(X11="Overstock",(V11-R11-S11)*E11,0) | AA11: =Q11*E11 | AB11: =IFERROR(G11*WeeksYear/(G11*CurrentCoverWks)*OrderCost+G11*CurrentCoverWks/2*E11*HoldRate,0) | AC11: =IFERROR(G11*WeeksYear/S11*OrderCost+S11/2*E11*HoldRate,0) | AD11: =AB11-AC11 | AE11: =IFERROR(INDEX(SegStrategy,MATCH(N11,SegList,0)),"") | AF11: =IF(D11=SimSupplier,COUNTIF($D$5:D11,SimSupplier),"") | AG11: =IF(OR(X11="Critical - expedite",X11="Order now"),COUNTIF($X$5:X11,"Critical - expedite")+COUNTIF($X$5:X11,"Order now"),"")
A12: =Products!A9 | B12: =Products!B9 | C12: =Products!C9 | D12: =Products!E9 | E12: =Products!D9 | F12: =SUMIFS(D_Units,D_SKU,A12,D_Last52,1) | G12: =IFERROR(AVERAGEIFS(D_Units,D_SKU,A12,D_Last52,1),0) | H12: =IFERROR(SQRT(MAX(0,(SUMIFS(D_Units2,D_SKU,A12)-COUNTIFS(D_SKU,A12,D_Last52,1)*G12^2)/(COUNTIFS(D_SKU,A12,D_Last52,1)-1))),0) | I12: =F12*E12 | J12: =IFERROR(SUMIF($I$5:$I$53,">"&I12)/SUM($I$5:$I$53),0) | K12: =IF(J12<ACut,"A",IF(J12<BCut,"B","C")) | L12: =IFERROR(H12/G12,0) | M12: =IF(L12<=XMaxCV,"X",IF(L12<=YMaxCV,"Y","Z")) | N12: =K12&M12 | O12: =IFERROR(INDEX(SC_LT,MATCH(D12,SC_ID,0)),0) | P12: =IFERROR(INDEX(SC_LTStd,MATCH(D12,SC_ID,0)),0) | Q12: =ROUNDUP(z*SQRT(O12*H12^2+G12^2*P12^2),0) | R12: =ROUNDUP(G12*O12+Q12,0) | S12: =IFERROR(ROUNDUP(SQRT(2*G12*WeeksYear*OrderCost/(E12*HoldRate)),0),0) | T12: =IFERROR(INDEX(Inventory!$B:$B,MATCH(A12,Inventory!$A:$A,0)),0) | U12: =IFERROR(INDEX(Inventory!$C:$C,MATCH(A12,Inventory!$A:$A,0)),0) | V12: =T12+U12 | W12: =IFERROR(T12/G12,0) | X12: =IF(V12<Q12,"Critical - expedite",IF(V12<=R12,"Order now",IF(V12>R12+S12,"Overstock","Healthy"))) | Y12: =IF(OR(X12="Critical - expedite",X12="Order now"),MAX(S12,R12+S12-V12),0) | Z12: =IF(X12="Overstock",(V12-R12-S12)*E12,0) | AA12: =Q12*E12 | AB12: =IFERROR(G12*WeeksYear/(G12*CurrentCoverWks)*OrderCost+G12*CurrentCoverWks/2*E12*HoldRate,0) | AC12: =IFERROR(G12*WeeksYear/S12*OrderCost+S12/2*E12*HoldRate,0) | AD12: =AB12-AC12 | AE12: =IFERROR(INDEX(SegStrategy,MATCH(N12,SegList,0)),"") | AF12: =IF(D12=SimSupplier,COUNTIF($D$5:D12,SimSupplier),"") | AG12: =IF(OR(X12="Critical - expedite",X12="Order now"),COUNTIF($X$5:X12,"Critical - expedite")+COUNTIF($X$5:X12,"Order now"),"")
A13: =Products!A10 | B13: =Products!B10 | C13: =Products!C10 | D13: =Products!E10 | E13: =Products!D10 | F13: =SUMIFS(D_Units,D_SKU,A13,D_Last52,1) | G13: =IFERROR(AVERAGEIFS(D_Units,D_SKU,A13,D_Last52,1),0) | H13: =IFERROR(SQRT(MAX(0,(SUMIFS(D_Units2,D_SKU,A13)-COUNTIFS(D_SKU,A13,D_Last52,1)*G13^2)/(COUNTIFS(D_SKU,A13,D_Last52,1)-1))),0) | I13: =F13*E13 | J13: =IFERROR(SUMIF($I$5:$I$53,">"&I13)/SUM($I$5:$I$53),0) | K13: =IF(J13<ACut,"A",IF(J13<BCut,"B","C")) | L13: =IFERROR(H13/G13,0) | M13: =IF(L13<=XMaxCV,"X",IF(L13<=YMaxCV,"Y","Z")) | N13: =K13&M13 | O13: =IFERROR(INDEX(SC_LT,MATCH(D13,SC_ID,0)),0) | P13: =IFERROR(INDEX(SC_LTStd,MATCH(D13,SC_ID,0)),0) | Q13: =ROUNDUP(z*SQRT(O13*H13^2+G13^2*P13^2),0) | R13: =ROUNDUP(G13*O13+Q13,0) | S13: =IFERROR(ROUNDUP(SQRT(2*G13*WeeksYear*OrderCost/(E13*HoldRate)),0),0) | T13: =IFERROR(INDEX(Inventory!$B:$B,MATCH(A13,Inventory!$A:$A,0)),0) | U13: =IFERROR(INDEX(Inventory!$C:$C,MATCH(A13,Inventory!$A:$A,0)),0) | V13: =T13+U13 | W13: =IFERROR(T13/G13,0) | X13: =IF(V13<Q13,"Critical - expedite",IF(V13<=R13,"Order now",IF(V13>R13+S13,"Overstock","Healthy"))) | Y13: =IF(OR(X13="Critical - expedite",X13="Order now"),MAX(S13,R13+S13-V13),0) | Z13: =IF(X13="Overstock",(V13-R13-S13)*E13,0) | AA13: =Q13*E13 | AB13: =IFERROR(G13*WeeksYear/(G13*CurrentCoverWks)*OrderCost+G13*CurrentCoverWks/2*E13*HoldRate,0) | AC13: =IFERROR(G13*WeeksYear/S13*OrderCost+S13/2*E13*HoldRate,0) | AD13: =AB13-AC13 | AE13: =IFERROR(INDEX(SegStrategy,MATCH(N13,SegList,0)),"") | AF13: =IF(D13=SimSupplier,COUNTIF($D$5:D13,SimSupplier),"") | AG13: =IF(OR(X13="Critical - expedite",X13="Order now"),COUNTIF($X$5:X13,"Critical - expedite")+COUNTIF($X$5:X13,"Order now"),"")
A14: =Products!A11 | B14: =Products!B11 | C14: =Products!C11 | D14: =Products!E11 | E14: =Products!D11 | F14: =SUMIFS(D_Units,D_SKU,A14,D_Last52,1) | G14: =IFERROR(AVERAGEIFS(D_Units,D_SKU,A14,D_Last52,1),0) | H14: =IFERROR(SQRT(MAX(0,(SUMIFS(D_Units2,D_SKU,A14)-COUNTIFS(D_SKU,A14,D_Last52,1)*G14^2)/(COUNTIFS(D_SKU,A14,D_Last52,1)-1))),0) | I14: =F14*E14 | J14: =IFERROR(SUMIF($I$5:$I$53,">"&I14)/SUM($I$5:$I$53),0) | K14: =IF(J14<ACut,"A",IF(J14<BCut,"B","C")) | L14: =IFERROR(H14/G14,0) | M14: =IF(L14<=XMaxCV,"X",IF(L14<=YMaxCV,"Y","Z")) | N14: =K14&M14 | O14: =IFERROR(INDEX(SC_LT,MATCH(D14,SC_ID,0)),0) | P14: =IFERROR(INDEX(SC_LTStd,MATCH(D14,SC_ID,0)),0) | Q14: =ROUNDUP(z*SQRT(O14*H14^2+G14^2*P14^2),0) | R14: =ROUNDUP(G14*O14+Q14,0) | S14: =IFERROR(ROUNDUP(SQRT(2*G14*WeeksYear*OrderCost/(E14*HoldRate)),0),0) | T14: =IFERROR(INDEX(Inventory!$B:$B,MATCH(A14,Inventory!$A:$A,0)),0) | U14: =IFERROR(INDEX(Inventory!$C:$C,MATCH(A14,Inventory!$A:$A,0)),0) | V14: =T14+U14 | W14: =IFERROR(T14/G14,0) | X14: =IF(V14<Q14,"Critical - expedite",IF(V14<=R14,"Order now",IF(V14>R14+S14,"Overstock","Healthy"))) | Y14: =IF(OR(X14="Critical - expedite",X14="Order now"),MAX(S14,R14+S14-V14),0) | Z14: =IF(X14="Overstock",(V14-R14-S14)*E14,0) | AA14: =Q14*E14 | AB14: =IFERROR(G14*WeeksYear/(G14*CurrentCoverWks)*OrderCost+G14*CurrentCoverWks/2*E14*HoldRate,0) | AC14: =IFERROR(G14*WeeksYear/S14*OrderCost+S14/2*E14*HoldRate,0) | AD14: =AB14-AC14 | AE14: =IFERROR(INDEX(SegStrategy,MATCH(N14,SegList,0)),"") | AF14: =IF(D14=SimSupplier,COUNTIF($D$5:D14,SimSupplier),"") | AG14: =IF(OR(X14="Critical - expedite",X14="Order now"),COUNTIF($X$5:X14,"Critical - expedite")+COUNTIF($X$5:X14,"Order now"),"")
A15: =Products!A12 | B15: =Products!B12 | C15: =Products!C12 | D15: =Products!E12 | E15: =Products!D12 | F15: =SUMIFS(D_Units,D_SKU,A15,D_Last52,1) | G15: =IFERROR(AVERAGEIFS(D_Units,D_SKU,A15,D_Last52,1),0) | H15: =IFERROR(SQRT(MAX(0,(SUMIFS(D_Units2,D_SKU,A15)-COUNTIFS(D_SKU,A15,D_Last52,1)*G15^2)/(COUNTIFS(D_SKU,A15,D_Last52,1)-1))),0) | I15: =F15*E15 | J15: =IFERROR(SUMIF($I$5:$I$53,">"&I15)/SUM($I$5:$I$53),0) | K15: =IF(J15<ACut,"A",IF(J15<BCut,"B","C")) | L15: =IFERROR(H15/G15,0) | M15: =IF(L15<=XMaxCV,"X",IF(L15<=YMaxCV,"Y","Z")) | N15: =K15&M15 | O15: =IFERROR(INDEX(SC_LT,MATCH(D15,SC_ID,0)),0) | P15: =IFERROR(INDEX(SC_LTStd,MATCH(D15,SC_ID,0)),0) | Q15: =ROUNDUP(z*SQRT(O15*H15^2+G15^2*P15^2),0) | R15: =ROUNDUP(G15*O15+Q15,0) | S15: =IFERROR(ROUNDUP(SQRT(2*G15*WeeksYear*OrderCost/(E15*HoldRate)),0),0) | T15: =IFERROR(INDEX(Inventory!$B:$B,MATCH(A15,Inventory!$A:$A,0)),0) | U15: =IFERROR(INDEX(Inventory!$C:$C,MATCH(A15,Inventory!$A:$A,0)),0) | V15: =T15+U15 | W15: =IFERROR(T15/G15,0) | X15: =IF(V15<Q15,"Critical - expedite",IF(V15<=R15,"Order now",IF(V15>R15+S15,"Overstock","Healthy"))) | Y15: =IF(OR(X15="Critical - expedite",X15="Order now"),MAX(S15,R15+S15-V15),0) | Z15: =IF(X15="Overstock",(V15-R15-S15)*E15,0) | AA15: =Q15*E15 | AB15: =IFERROR(G15*WeeksYear/(G15*CurrentCoverWks)*OrderCost+G15*CurrentCoverWks/2*E15*HoldRate,0) | AC15: =IFERROR(G15*WeeksYear/S15*OrderCost+S15/2*E15*HoldRate,0) | AD15: =AB15-AC15 | AE15: =IFERROR(INDEX(SegStrategy,MATCH(N15,SegList,0)),"") | AF15: =IF(D15=SimSupplier,COUNTIF($D$5:D15,SimSupplier),"") | AG15: =IF(OR(X15="Critical - expedite",X15="Order now"),COUNTIF($X$5:X15,"Critical - expedite")+COUNTIF($X$5:X15,"Order now"),"")
A16: =Products!A13 | B16: =Products!B13 | C16: =Products!C13 | D16: =Products!E13 | E16: =Products!D13 | F16: =SUMIFS(D_Units,D_SKU,A16,D_Last52,1) | G16: =IFERROR(AVERAGEIFS(D_Units,D_SKU,A16,D_Last52,1),0) | H16: =IFERROR(SQRT(MAX(0,(SUMIFS(D_Units2,D_SKU,A16)-COUNTIFS(D_SKU,A16,D_Last52,1)*G16^2)/(COUNTIFS(D_SKU,A16,D_Last52,1)-1))),0) | I16: =F16*E16 | J16: =IFERROR(SUMIF($I$5:$I$53,">"&I16)/SUM($I$5:$I$53),0) | K16: =IF(J16<ACut,"A",IF(J16<BCut,"B","C")) | L16: =IFERROR(H16/G16,0) | M16: =IF(L16<=XMaxCV,"X",IF(L16<=YMaxCV,"Y","Z")) | N16: =K16&M16 | O16: =IFERROR(INDEX(SC_LT,MATCH(D16,SC_ID,0)),0) | P16: =IFERROR(INDEX(SC_LTStd,MATCH(D16,SC_ID,0)),0) | Q16: =ROUNDUP(z*SQRT(O16*H16^2+G16^2*P16^2),0) | R16: =ROUNDUP(G16*O16+Q16,0) | S16: =IFERROR(ROUNDUP(SQRT(2*G16*WeeksYear*OrderCost/(E16*HoldRate)),0),0) | T16: =IFERROR(INDEX(Inventory!$B:$B,MATCH(A16,Inventory!$A:$A,0)),0) | U16: =IFERROR(INDEX(Inventory!$C:$C,MATCH(A16,Inventory!$A:$A,0)),0) | V16: =T16+U16 | W16: =IFERROR(T16/G16,0) | X16: =IF(V16<Q16,"Critical - expedite",IF(V16<=R16,"Order now",IF(V16>R16+S16,"Overstock","Healthy"))) | Y16: =IF(OR(X16="Critical - expedite",X16="Order now"),MAX(S16,R16+S16-V16),0) | Z16: =IF(X16="Overstock",(V16-R16-S16)*E16,0) | AA16: =Q16*E16 | AB16: =IFERROR(G16*WeeksYear/(G16*CurrentCoverWks)*OrderCost+G16*CurrentCoverWks/2*E16*HoldRate,0) | AC16: =IFERROR(G16*WeeksYear/S16*OrderCost+S16/2*E16*HoldRate,0) | AD16: =AB16-AC16 | AE16: =IFERROR(INDEX(SegStrategy,MATCH(N16,SegList,0)),"") | AF16: =IF(D16=SimSupplier,COUNTIF($D$5:D16,SimSupplier),"") | AG16: =IF(OR(X16="Critical - expedite",X16="Order now"),COUNTIF($X$5:X16,"Critical - expedite")+COUNTIF($X$5:X16,"Order now"),"")
... A53: =Products!A50 | B53: =Products!B50 | C53: =Products!C50 | D53: =Products!E50 | E53: =Products!D50 | F53: =SUMIFS(D_Units,D_SKU,A53,D_Last52,1) | G53: =IFERROR(AVERAGEIFS(D_Units,D_SKU,A53,D_Last52,1),0) | H53: =IFERROR(SQRT(MAX(0,(SUMIFS(D_Units2,D_SKU,A53)-COUNTIFS(D_SKU,A53,D_Last52,1)*G53^2)/(COUNTIFS(D_SKU,A53,D_Last52,1)-1))),0) | I53: =F53*E53 | J53: =IFERROR(SUMIF($I$5:$I$53,">"&I53)/SUM($I$5:$I$53),0) | K53: =IF(J53<ACut,"A",IF(J53<BCut,"B","C")) | L53: =IFERROR(H53/G53,0) | M53: =IF(L53<=XMaxCV,"X",IF(L53<=YMaxCV,"Y","Z")) | N53: =K53&M53 | O53: =IFERROR(INDEX(SC_LT,MATCH(D53,SC_ID,0)),0) | P53: =IFERROR(INDEX(SC_LTStd,MATCH(D53,SC_ID,0)),0) | Q53: =ROUNDUP(z*SQRT(O53*H53^2+G53^2*P53^2),0) | R53: =ROUNDUP(G53*O53+Q53,0) | S53: =IFERROR(ROUNDUP(SQRT(2*G53*WeeksYear*OrderCost/(E53*HoldRate)),0),0) | T53: =IFERROR(INDEX(Inventory!$B:$B,MATCH(A53,Inventory!$A:$A,0)),0) | U53: =IFERROR(INDEX(Inventory!$C:$C,MATCH(A53,Inventory!$A:$A,0)),0) | V53: =T53+U53 | W53: =IFERROR(T53/G53,0) | X53: =IF(V53<Q53,"Critical - expedite",IF(V53<=R53,"Order now",IF(V53>R53+S53,"Overstock","Healthy"))) | Y53: =IF(OR(X53="Critical - expedite",X53="Order now"),MAX(S53,R53+S53-V53),0) | Z53: =IF(X53="Overstock",(V53-R53-S53)*E53,0) | AA53: =Q53*E53 | AB53: =IFERROR(G53*WeeksYear/(G53*CurrentCoverWks)*OrderCost+G53*CurrentCoverWks/2*E53*HoldRate,0) | AC53: =IFERROR(G53*WeeksYear/S53*OrderCost+S53/2*E53*HoldRate,0) | AD53: =AB53-AC53 | AE53: =IFERROR(INDEX(SegStrategy,MATCH(N53,SegList,0)),"") | AF53: =IF(D53=SimSupplier,COUNTIF($D$5:D53,SimSupplier),"") | AG53: =IF(OR(X53="Critical - expedite",X53="Order now"),COUNTIF($X$5:X53,"Critical - expedite")+COUNTIF($X$5:X53,"Order now"),"")

Sheet Supplier_Scorecard
A1: Supplier Scorecard & Risk Score
A2: Every column is a formula over the Purchase_Orders sheet. Weights and thresholds are on the Assumptions sheet.
T3: Weighted contribution of each factor (used to find the main driver)
A4: Supplier ID | B4: Supplier | C4: Country | D4: POs | E4: Spend (CAD) | F4: Share of spend | G4: On-time delivery | H4: Avg days late | I4: Avg lead time (wks) | J4: Lead time std (wks) | K4: Lead time CV | L4: Fill rate | M4: Defect rate | N4: Country risk (1-5) | O4: Factor: late | P4: Factor: LT variability | Q4: Factor: quality | R4: Factor: country | S4: Factor: spend | T4: late delivery | U4: lead time variability | V4: quality | W4: country risk | X4: spend dependency | Y4: Risk score (0-100) | Z4: Risk tier | AA4: Main risk driver | AB4: Recommended action | AC4: Risk rank
A5: =Suppliers!A2 | B5: =Suppliers!B2 | C5: =Suppliers!C2 | D5: =COUNTIF(PO_Sup,A5) | E5: =SUMIF(PO_Sup,A5,PO_Value) | F5: =IFERROR(E5/SUM($E$5:$E$12),0) | G5: =IFERROR(AVERAGEIF(PO_Sup,A5,PO_OnTime),0) | H5: =IFERROR(AVERAGEIF(PO_Sup,A5,PO_DaysLate),0) | I5: =IFERROR(AVERAGEIF(PO_Sup,A5,PO_LT),0) | J5: =IFERROR(SQRT(MAX(0,(SUMIF(PO_Sup,A5,PO_LT2)-D5*I5^2)/(D5-1))),0) | K5: =IFERROR(J5/I5,0) | L5: =IFERROR(SUMIF(PO_Sup,A5,PO_QtyRec)/SUMIF(PO_Sup,A5,PO_QtyOrd),0) | M5: =IFERROR(SUMIF(PO_Sup,A5,PO_QtyDef)/SUMIF(PO_Sup,A5,PO_QtyRec),0) | N5: =IFERROR(INDEX(CountryScore,MATCH(C5,CountryList,0)),3) | O5: =MIN(1,MAX(0,(1-G5)/BadLate)) | P5: =MIN(1,MAX(0,K5/BadLTV)) | Q5: =MIN(1,MAX(0,M5/BadQuality)) | R5: =MIN(1,MAX(0,(N5-1)/4)) | S5: =MIN(1,MAX(0,F5/BadSpend)) | T5: =O5*wLate | U5: =P5*wLTV | V5: =Q5*wQuality | W5: =R5*wCountry | X5: =S5*wSpend | Y5: =ROUND(SUM(T5:X5)*100,1) | Z5: =IF(Y5>60,"High",IF(Y5>35,"Medium","Low")) | AA5: =INDEX($T$4:$X$4,MATCH(MAX(T5:X5),T5:X5,0)) | AB5: =IF(AND(Z5="Low",F5>=0.25),"Reliable, but holds a large share of spend: keep as primary and qualify a backup supplier for its A-class SKUs",IF(Z5="Low","Maintain; candidate for volume consolidation / preferred-supplier status",IF(Z5="High","Priority: ","")&INDEX(DriverAction,MATCH(AA5,DriverList,0)))) | AC5: =RANK(Y5,$Y$5:$Y$12)
A6: =Suppliers!A3 | B6: =Suppliers!B3 | C6: =Suppliers!C3 | D6: =COUNTIF(PO_Sup,A6) | E6: =SUMIF(PO_Sup,A6,PO_Value) | F6: =IFERROR(E6/SUM($E$5:$E$12),0) | G6: =IFERROR(AVERAGEIF(PO_Sup,A6,PO_OnTime),0) | H6: =IFERROR(AVERAGEIF(PO_Sup,A6,PO_DaysLate),0) | I6: =IFERROR(AVERAGEIF(PO_Sup,A6,PO_LT),0) | J6: =IFERROR(SQRT(MAX(0,(SUMIF(PO_Sup,A6,PO_LT2)-D6*I6^2)/(D6-1))),0) | K6: =IFERROR(J6/I6,0) | L6: =IFERROR(SUMIF(PO_Sup,A6,PO_QtyRec)/SUMIF(PO_Sup,A6,PO_QtyOrd),0) | M6: =IFERROR(SUMIF(PO_Sup,A6,PO_QtyDef)/SUMIF(PO_Sup,A6,PO_QtyRec),0) | N6: =IFERROR(INDEX(CountryScore,MATCH(C6,CountryList,0)),3) | O6: =MIN(1,MAX(0,(1-G6)/BadLate)) | P6: =MIN(1,MAX(0,K6/BadLTV)) | Q6: =MIN(1,MAX(0,M6/BadQuality)) | R6: =MIN(1,MAX(0,(N6-1)/4)) | S6: =MIN(1,MAX(0,F6/BadSpend)) | T6: =O6*wLate | U6: =P6*wLTV | V6: =Q6*wQuality | W6: =R6*wCountry | X6: =S6*wSpend | Y6: =ROUND(SUM(T6:X6)*100,1) | Z6: =IF(Y6>60,"High",IF(Y6>35,"Medium","Low")) | AA6: =INDEX($T$4:$X$4,MATCH(MAX(T6:X6),T6:X6,0)) | AB6: =IF(AND(Z6="Low",F6>=0.25),"Reliable, but holds a large share of spend: keep as primary and qualify a backup supplier for its A-class SKUs",IF(Z6="Low","Maintain; candidate for volume consolidation / preferred-supplier status",IF(Z6="High","Priority: ","")&INDEX(DriverAction,MATCH(AA6,DriverList,0)))) | AC6: =RANK(Y6,$Y$5:$Y$12)
A7: =Suppliers!A4 | B7: =Suppliers!B4 | C7: =Suppliers!C4 | D7: =COUNTIF(PO_Sup,A7) | E7: =SUMIF(PO_Sup,A7,PO_Value) | F7: =IFERROR(E7/SUM($E$5:$E$12),0) | G7: =IFERROR(AVERAGEIF(PO_Sup,A7,PO_OnTime),0) | H7: =IFERROR(AVERAGEIF(PO_Sup,A7,PO_DaysLate),0) | I7: =IFERROR(AVERAGEIF(PO_Sup,A7,PO_LT),0) | J7: =IFERROR(SQRT(MAX(0,(SUMIF(PO_Sup,A7,PO_LT2)-D7*I7^2)/(D7-1))),0) | K7: =IFERROR(J7/I7,0) | L7: =IFERROR(SUMIF(PO_Sup,A7,PO_QtyRec)/SUMIF(PO_Sup,A7,PO_QtyOrd),0) | M7: =IFERROR(SUMIF(PO_Sup,A7,PO_QtyDef)/SUMIF(PO_Sup,A7,PO_QtyRec),0) | N7: =IFERROR(INDEX(CountryScore,MATCH(C7,CountryList,0)),3) | O7: =MIN(1,MAX(0,(1-G7)/BadLate)) | P7: =MIN(1,MAX(0,K7/BadLTV)) | Q7: =MIN(1,MAX(0,M7/BadQuality)) | R7: =MIN(1,MAX(0,(N7-1)/4)) | S7: =MIN(1,MAX(0,F7/BadSpend)) | T7: =O7*wLate | U7: =P7*wLTV | V7: =Q7*wQuality | W7: =R7*wCountry | X7: =S7*wSpend | Y7: =ROUND(SUM(T7:X7)*100,1) | Z7: =IF(Y7>60,"High",IF(Y7>35,"Medium","Low")) | AA7: =INDEX($T$4:$X$4,MATCH(MAX(T7:X7),T7:X7,0)) | AB7: =IF(AND(Z7="Low",F7>=0.25),"Reliable, but holds a large share of spend: keep as primary and qualify a backup supplier for its A-class SKUs",IF(Z7="Low","Maintain; candidate for volume consolidation / preferred-supplier status",IF(Z7="High","Priority: ","")&INDEX(DriverAction,MATCH(AA7,DriverList,0)))) | AC7: =RANK(Y7,$Y$5:$Y$12)
A8: =Suppliers!A5 | B8: =Suppliers!B5 | C8: =Suppliers!C5 | D8: =COUNTIF(PO_Sup,A8) | E8: =SUMIF(PO_Sup,A8,PO_Value) | F8: =IFERROR(E8/SUM($E$5:$E$12),0) | G8: =IFERROR(AVERAGEIF(PO_Sup,A8,PO_OnTime),0) | H8: =IFERROR(AVERAGEIF(PO_Sup,A8,PO_DaysLate),0) | I8: =IFERROR(AVERAGEIF(PO_Sup,A8,PO_LT),0) | J8: =IFERROR(SQRT(MAX(0,(SUMIF(PO_Sup,A8,PO_LT2)-D8*I8^2)/(D8-1))),0) | K8: =IFERROR(J8/I8,0) | L8: =IFERROR(SUMIF(PO_Sup,A8,PO_QtyRec)/SUMIF(PO_Sup,A8,PO_QtyOrd),0) | M8: =IFERROR(SUMIF(PO_Sup,A8,PO_QtyDef)/SUMIF(PO_Sup,A8,PO_QtyRec),0) | N8: =IFERROR(INDEX(CountryScore,MATCH(C8,CountryList,0)),3) | O8: =MIN(1,MAX(0,(1-G8)/BadLate)) | P8: =MIN(1,MAX(0,K8/BadLTV)) | Q8: =MIN(1,MAX(0,M8/BadQuality)) | R8: =MIN(1,MAX(0,(N8-1)/4)) | S8: =MIN(1,MAX(0,F8/BadSpend)) | T8: =O8*wLate | U8: =P8*wLTV | V8: =Q8*wQuality | W8: =R8*wCountry | X8: =S8*wSpend | Y8: =ROUND(SUM(T8:X8)*100,1) | Z8: =IF(Y8>60,"High",IF(Y8>35,"Medium","Low")) | AA8: =INDEX($T$4:$X$4,MATCH(MAX(T8:X8),T8:X8,0)) | AB8: =IF(AND(Z8="Low",F8>=0.25),"Reliable, but holds a large share of spend: keep as primary and qualify a backup supplier for its A-class SKUs",IF(Z8="Low","Maintain; candidate for volume consolidation / preferred-supplier status",IF(Z8="High","Priority: ","")&INDEX(DriverAction,MATCH(AA8,DriverList,0)))) | AC8: =RANK(Y8,$Y$5:$Y$12)
A9: =Suppliers!A6 | B9: =Suppliers!B6 | C9: =Suppliers!C6 | D9: =COUNTIF(PO_Sup,A9) | E9: =SUMIF(PO_Sup,A9,PO_Value) | F9: =IFERROR(E9/SUM($E$5:$E$12),0) | G9: =IFERROR(AVERAGEIF(PO_Sup,A9,PO_OnTime),0) | H9: =IFERROR(AVERAGEIF(PO_Sup,A9,PO_DaysLate),0) | I9: =IFERROR(AVERAGEIF(PO_Sup,A9,PO_LT),0) | J9: =IFERROR(SQRT(MAX(0,(SUMIF(PO_Sup,A9,PO_LT2)-D9*I9^2)/(D9-1))),0) | K9: =IFERROR(J9/I9,0) | L9: =IFERROR(SUMIF(PO_Sup,A9,PO_QtyRec)/SUMIF(PO_Sup,A9,PO_QtyOrd),0) | M9: =IFERROR(SUMIF(PO_Sup,A9,PO_QtyDef)/SUMIF(PO_Sup,A9,PO_QtyRec),0) | N9: =IFERROR(INDEX(CountryScore,MATCH(C9,CountryList,0)),3) | O9: =MIN(1,MAX(0,(1-G9)/BadLate)) | P9: =MIN(1,MAX(0,K9/BadLTV)) | Q9: =MIN(1,MAX(0,M9/BadQuality)) | R9: =MIN(1,MAX(0,(N9-1)/4)) | S9: =MIN(1,MAX(0,F9/BadSpend)) | T9: =O9*wLate | U9: =P9*wLTV | V9: =Q9*wQuality | W9: =R9*wCountry | X9: =S9*wSpend | Y9: =ROUND(SUM(T9:X9)*100,1) | Z9: =IF(Y9>60,"High",IF(Y9>35,"Medium","Low")) | AA9: =INDEX($T$4:$X$4,MATCH(MAX(T9:X9),T9:X9,0)) | AB9: =IF(AND(Z9="Low",F9>=0.25),"Reliable, but holds a large share of spend: keep as primary and qualify a backup supplier for its A-class SKUs",IF(Z9="Low","Maintain; candidate for volume consolidation / preferred-supplier status",IF(Z9="High","Priority: ","")&INDEX(DriverAction,MATCH(AA9,DriverList,0)))) | AC9: =RANK(Y9,$Y$5:$Y$12)
A10: =Suppliers!A7 | B10: =Suppliers!B7 | C10: =Suppliers!C7 | D10: =COUNTIF(PO_Sup,A10) | E10: =SUMIF(PO_Sup,A10,PO_Value) | F10: =IFERROR(E10/SUM($E$5:$E$12),0) | G10: =IFERROR(AVERAGEIF(PO_Sup,A10,PO_OnTime),0) | H10: =IFERROR(AVERAGEIF(PO_Sup,A10,PO_DaysLate),0) | I10: =IFERROR(AVERAGEIF(PO_Sup,A10,PO_LT),0) | J10: =IFERROR(SQRT(MAX(0,(SUMIF(PO_Sup,A10,PO_LT2)-D10*I10^2)/(D10-1))),0) | K10: =IFERROR(J10/I10,0) | L10: =IFERROR(SUMIF(PO_Sup,A10,PO_QtyRec)/SUMIF(PO_Sup,A10,PO_QtyOrd),0) | M10: =IFERROR(SUMIF(PO_Sup,A10,PO_QtyDef)/SUMIF(PO_Sup,A10,PO_QtyRec),0) | N10: =IFERROR(INDEX(CountryScore,MATCH(C10,CountryList,0)),3) | O10: =MIN(1,MAX(0,(1-G10)/BadLate)) | P10: =MIN(1,MAX(0,K10/BadLTV)) | Q10: =MIN(1,MAX(0,M10/BadQuality)) | R10: =MIN(1,MAX(0,(N10-1)/4)) | S10: =MIN(1,MAX(0,F10/BadSpend)) | T10: =O10*wLate | U10: =P10*wLTV | V10: =Q10*wQuality | W10: =R10*wCountry | X10: =S10*wSpend | Y10: =ROUND(SUM(T10:X10)*100,1) | Z10: =IF(Y10>60,"High",IF(Y10>35,"Medium","Low")) | AA10: =INDEX($T$4:$X$4,MATCH(MAX(T10:X10),T10:X10,0)) | AB10: =IF(AND(Z10="Low",F10>=0.25),"Reliable, but holds a large share of spend: keep as primary and qualify a backup supplier for its A-class SKUs",IF(Z10="Low","Maintain; candidate for volume consolidation / preferred-supplier status",IF(Z10="High","Priority: ","")&INDEX(DriverAction,MATCH(AA10,DriverList,0)))) | AC10: =RANK(Y10,$Y$5:$Y$12)
A11: =Suppliers!A8 | B11: =Suppliers!B8 | C11: =Suppliers!C8 | D11: =COUNTIF(PO_Sup,A11) | E11: =SUMIF(PO_Sup,A11,PO_Value) | F11: =IFERROR(E11/SUM($E$5:$E$12),0) | G11: =IFERROR(AVERAGEIF(PO_Sup,A11,PO_OnTime),0) | H11: =IFERROR(AVERAGEIF(PO_Sup,A11,PO_DaysLate),0) | I11: =IFERROR(AVERAGEIF(PO_Sup,A11,PO_LT),0) | J11: =IFERROR(SQRT(MAX(0,(SUMIF(PO_Sup,A11,PO_LT2)-D11*I11^2)/(D11-1))),0) | K11: =IFERROR(J11/I11,0) | L11: =IFERROR(SUMIF(PO_Sup,A11,PO_QtyRec)/SUMIF(PO_Sup,A11,PO_QtyOrd),0) | M11: =IFERROR(SUMIF(PO_Sup,A11,PO_QtyDef)/SUMIF(PO_Sup,A11,PO_QtyRec),0) | N11: =IFERROR(INDEX(CountryScore,MATCH(C11,CountryList,0)),3) | O11: =MIN(1,MAX(0,(1-G11)/BadLate)) | P11: =MIN(1,MAX(0,K11/BadLTV)) | Q11: =MIN(1,MAX(0,M11/BadQuality)) | R11: =MIN(1,MAX(0,(N11-1)/4)) | S11: =MIN(1,MAX(0,F11/BadSpend)) | T11: =O11*wLate | U11: =P11*wLTV | V11: =Q11*wQuality | W11: =R11*wCountry | X11: =S11*wSpend | Y11: =ROUND(SUM(T11:X11)*100,1) | Z11: =IF(Y11>60,"High",IF(Y11>35,"Medium","Low")) | AA11: =INDEX($T$4:$X$4,MATCH(MAX(T11:X11),T11:X11,0)) | AB11: =IF(AND(Z11="Low",F11>=0.25),"Reliable, but holds a large share of spend: keep as primary and qualify a backup supplier for its A-class SKUs",IF(Z11="Low","Maintain; candidate for volume consolidation / preferred-supplier status",IF(Z11="High","Priority: ","")&INDEX(DriverAction,MATCH(AA11,DriverList,0)))) | AC11: =RANK(Y11,$Y$5:$Y$12)
A12: =Suppliers!A9 | B12: =Suppliers!B9 | C12: =Suppliers!C9 | D12: =COUNTIF(PO_Sup,A12) | E12: =SUMIF(PO_Sup,A12,PO_Value) | F12: =IFERROR(E12/SUM($E$5:$E$12),0) | G12: =IFERROR(AVERAGEIF(PO_Sup,A12,PO_OnTime),0) | H12: =IFERROR(AVERAGEIF(PO_Sup,A12,PO_DaysLate),0) | I12: =IFERROR(AVERAGEIF(PO_Sup,A12,PO_LT),0) | J12: =IFERROR(SQRT(MAX(0,(SUMIF(PO_Sup,A12,PO_LT2)-D12*I12^2)/(D12-1))),0) | K12: =IFERROR(J12/I12,0) | L12: =IFERROR(SUMIF(PO_Sup,A12,PO_QtyRec)/SUMIF(PO_Sup,A12,PO_QtyOrd),0) | M12: =IFERROR(SUMIF(PO_Sup,A12,PO_QtyDef)/SUMIF(PO_Sup,A12,PO_QtyRec),0) | N12: =IFERROR(INDEX(CountryScore,MATCH(C12,CountryList,0)),3) | O12: =MIN(1,MAX(0,(1-G12)/BadLate)) | P12: =MIN(1,MAX(0,K12/BadLTV)) | Q12: =MIN(1,MAX(0,M12/BadQuality)) | R12: =MIN(1,MAX(0,(N12-1)/4)) | S12: =MIN(1,MAX(0,F12/BadSpend)) | T12: =O12*wLate | U12: =P12*wLTV | V12: =Q12*wQuality | W12: =R12*wCountry | X12: =S12*wSpend | Y12: =ROUND(SUM(T12:X12)*100,1) | Z12: =IF(Y12>60,"High",IF(Y12>35,"Medium","Low")) | AA12: =INDEX($T$4:$X$4,MATCH(MAX(T12:X12),T12:X12,0)) | AB12: =IF(AND(Z12="Low",F12>=0.25),"Reliable, but holds a large share of spend: keep as primary and qualify a backup supplier for its A-class SKUs",IF(Z12="Low","Maintain; candidate for volume consolidation / preferred-supplier status",IF(Z12="High","Priority: ","")&INDEX(DriverAction,MATCH(AA12,DriverList,0)))) | AC12: =RANK(Y12,$Y$5:$Y$12)

Sheet Forecast
A1: Demand Forecast Back-test (one SKU at a time)
A2: Pick a SKU. Three methods forecast each week one step ahead; accuracy (WAPE) is measured on the last 12 weeks.
A4: SKU (pick from list) | B4: NB-0001
A5: Product | B5: =IFERROR(INDEX(P_Name,MATCH(FcSKU,P_SKU,0)),"")
A6: Smoothing factor alpha (0-1) | B6: 0.3
A7: Test window (weeks) | B7: 12
A9: Accuracy on last 12 weeks
A10: Moving avg (4w) | B10: =IFERROR(SUMPRODUCT(ABS($C$109:$C$120-D109:D120))/SUM($C$109:$C$120),0) | C10: WAPE = sum(|actual - forecast|) / sum(actual)
A11: Exp. smoothing | B11: =IFERROR(SUMPRODUCT(ABS($C$109:$C$120-F109:F120))/SUM($C$109:$C$120),0)
A12: Seasonal naive | B12: =IFERROR(SUMPRODUCT(ABS($C$109:$C$120-G109:G120))/SUM($C$109:$C$120),0)
A13: Best method (lowest WAPE) | B13: =INDEX(A10:A12,MATCH(MIN(B10:B12),B10:B12,0))
A14: Next 12 weeks, best method (units) | B14: =SUM(H121:H132)
A15: Best method index (1-3) | B15: =MATCH(MIN(B10:B12),B10:B12,0)
A16: Week # | B16: Week start | C16: Actual units | D16: Moving avg (4w) | E16: SES level | F16: Exp. smoothing | G16: Seasonal naive | H16: Best method
A17: 1 | B17: 45292 | C17: =SUMIFS(D_Units,D_SKU,FcSKU,D_Week,B17) | E17: =C17
A18: 2 | B18: 45299 | C18: =SUMIFS(D_Units,D_SKU,FcSKU,D_Week,B18) | E18: =Alpha*C18+(1-Alpha)*E17 | F18: =E17
A19: 3 | B19: 45306 | C19: =SUMIFS(D_Units,D_SKU,FcSKU,D_Week,B19) | E19: =Alpha*C19+(1-Alpha)*E18 | F19: =E18
A20: 4 | B20: 45313 | C20: =SUMIFS(D_Units,D_SKU,FcSKU,D_Week,B20) | E20: =Alpha*C20+(1-Alpha)*E19 | F20: =E19
A21: 5 | B21: 45320 | C21: =SUMIFS(D_Units,D_SKU,FcSKU,D_Week,B21) | D21: =AVERAGE(C17:C20) | E21: =Alpha*C21+(1-Alpha)*E20 | F21: =E20
A22: 6 | B22: 45327 | C22: =SUMIFS(D_Units,D_SKU,FcSKU,D_Week,B22) | D22: =AVERAGE(C18:C21) | E22: =Alpha*C22+(1-Alpha)*E21 | F22: =E21
A23: 7 | B23: 45334 | C23: =SUMIFS(D_Units,D_SKU,FcSKU,D_Week,B23) | D23: =AVERAGE(C19:C22) | E23: =Alpha*C23+(1-Alpha)*E22 | F23: =E22
A24: 8 | B24: 45341 | C24: =SUMIFS(D_Units,D_SKU,FcSKU,D_Week,B24) | D24: =AVERAGE(C20:C23) | E24: =Alpha*C24+(1-Alpha)*E23 | F24: =E23
A25: 9 | B25: 45348 | C25: =SUMIFS(D_Units,D_SKU,FcSKU,D_Week,B25) | D25: =AVERAGE(C21:C24) | E25: =Alpha*C25+(1-Alpha)*E24 | F25: =E24
A26: 10 | B26: 45355 | C26: =SUMIFS(D_Units,D_SKU,FcSKU,D_Week,B26) | D26: =AVERAGE(C22:C25) | E26: =Alpha*C26+(1-Alpha)*E25 | F26: =E25
A27: 11 | B27: 45362 | C27: =SUMIFS(D_Units,D_SKU,FcSKU,D_Week,B27) | D27: =AVERAGE(C23:C26) | E27: =Alpha*C27+(1-Alpha)*E26 | F27: =E26
A28: 12 | B28: 45369 | C28: =SUMIFS(D_Units,D_SKU,FcSKU,D_Week,B28) | D28: =AVERAGE(C24:C27) | E28: =Alpha*C28+(1-Alpha)*E27 | F28: =E27
A29: 13 | B29: 45376 | C29: =SUMIFS(D_Units,D_SKU,FcSKU,D_Week,B29) | D29: =AVERAGE(C25:C28) | E29: =Alpha*C29+(1-Alpha)*E28 | F29: =E28
A30: 14 | B30: 45383 | C30: =SUMIFS(D_Units,D_SKU,FcSKU,D_Week,B30) | D30: =AVERAGE(C26:C29) | E30: =Alpha*C30+(1-Alpha)*E29 | F30: =E29
A31: 15 | B31: 45390 | C31: =SUMIFS(D_Units,D_SKU,FcSKU,D_Week,B31) | D31: =AVERAGE(C27:C30) | E31: =Alpha*C31+(1-Alpha)*E30 | F31: =E30
A32: 16 | B32: 45397 | C32: =SUMIFS(D_Units,D_SKU,FcSKU,D_Week,B32) | D32: =AVERAGE(C28:C31) | E32: =Alpha*C32+(1-Alpha)*E31 | F32: =E31
... A68: 52 | B68: 45649 | C68: =SUMIFS(D_Units,D_SKU,FcSKU,D_Week,B68) | D68: =AVERAGE(C64:C67) | E68: =Alpha*C68+(1-Alpha)*E67 | F68: =E67
A69: 53 | B69: 45656 | C69: =SUMIFS(D_Units,D_SKU,FcSKU,D_Week,B69) | D69: =AVERAGE(C65:C68) | E69: =Alpha*C69+(1-Alpha)*E68 | F69: =E68 | G69: =C17
A70: 54 | B70: 45663 | C70: =SUMIFS(D_Units,D_SKU,FcSKU,D_Week,B70) | D70: =AVERAGE(C66:C69) | E70: =Alpha*C70+(1-Alpha)*E69 | F70: =E69 | G70: =C18
A71: 55 | B71: 45670 | C71: =SUMIFS(D_Units,D_SKU,FcSKU,D_Week,B71) | D71: =AVERAGE(C67:C70) | E71: =Alpha*C71+(1-Alpha)*E70 | F71: =E70 | G71: =C19
A72: 56 | B72: 45677 | C72: =SUMIFS(D_Units,D_SKU,FcSKU,D_Week,B72) | D72: =AVERAGE(C68:C71) | E72: =Alpha*C72+(1-Alpha)*E71 | F72: =E71 | G72: =C20
A73: 57 | B73: 45684 | C73: =SUMIFS(D_Units,D_SKU,FcSKU,D_Week,B73) | D73: =AVERAGE(C69:C72) | E73: =Alpha*C73+(1-Alpha)*E72 | F73: =E72 | G73: =C21
A74: 58 | B74: 45691 | C74: =SUMIFS(D_Units,D_SKU,FcSKU,D_Week,B74) | D74: =AVERAGE(C70:C73) | E74: =Alpha*C74+(1-Alpha)*E73 | F74: =E73 | G74: =C22
A75: 59 | B75: 45698 | C75: =SUMIFS(D_Units,D_SKU,FcSKU,D_Week,B75) | D75: =AVERAGE(C71:C74) | E75: =Alpha*C75+(1-Alpha)*E74 | F75: =E74 | G75: =C23
A76: 60 | B76: 45705 | C76: =SUMIFS(D_Units,D_SKU,FcSKU,D_Week,B76) | D76: =AVERAGE(C72:C75) | E76: =Alpha*C76+(1-Alpha)*E75 | F76: =E75 | G76: =C24
A77: 61 | B77: 45712 | C77: =SUMIFS(D_Units,D_SKU,FcSKU,D_Week,B77) | D77: =AVERAGE(C73:C76) | E77: =Alpha*C77+(1-Alpha)*E76 | F77: =E76 | G77: =C25
...

Sheet Disruption_Simulator
A1: Disruption Simulator
A2: What if a supplier is delayed (port strike, tariff hold, factory shutdown)? Pick a supplier and a delay.
A4: Supplier (pick from list) | B4: S08 | C4: =IFERROR(INDEX(Supplier_Scorecard!$B$5:$B$12,MATCH(B4,SC_ID,0)),"")
A5: Extra delay (weeks) | B5: 4
A7: SKUs that stock out | B7: =COUNTIF(J13:J42,"Stockout")&" of "&COUNTIF(P_Sup,SimSupplier)
A8: Revenue at risk (CAD) | B8: =SUM(L13:L42)
A9: Extra buffer stock to prevent it (CAD) | B9: =SUM(N13:N42)
A12: # | B12: SKU | C12: Product | D12: ABC | E12: Avg weekly demand | F12: On hand + on order | G12: Weeks of stock | H12: Lead time (wks) | I12: New lead time | J12: Outcome | K12: Units short | L12: Revenue at risk (CAD) | M12: Buffer units | N12: Buffer cost (CAD) | O12: row
A13: 1 | B13: =IF(O13="","",INDEX(P_SKU,O13)) | C13: =IF(O13="","",INDEX(P_Name,O13)) | D13: =IF(O13="","",INDEX(P_ABC,O13)) | E13: =IF(O13="","",INDEX(P_Demand,O13)) | F13: =IF(O13="","",INDEX(P_Pos,O13)) | G13: =IF(O13="","",IFERROR(F13/E13,999)) | H13: =IF(O13="","",INDEX(P_LT,O13)) | I13: =IF(O13="","",H13+SimDelay) | J13: =IF(O13="","",IF(I13>G13,"Stockout","Covered")) | K13: =IF(O13="","",ROUNDUP(MAX(0,I13-G13)*E13,0)) | L13: =IF(O13="","",K13*INDEX(P_Cost,O13)*Markup) | M13: =IF(O13="","",ROUNDUP(E13*SimDelay,0)) | N13: =IF(O13="","",M13*INDEX(P_Cost,O13)) | O13: =IFERROR(MATCH(A13,P_SimRow,0),"")
A14: 2 | B14: =IF(O14="","",INDEX(P_SKU,O14)) | C14: =IF(O14="","",INDEX(P_Name,O14)) | D14: =IF(O14="","",INDEX(P_ABC,O14)) | E14: =IF(O14="","",INDEX(P_Demand,O14)) | F14: =IF(O14="","",INDEX(P_Pos,O14)) | G14: =IF(O14="","",IFERROR(F14/E14,999)) | H14: =IF(O14="","",INDEX(P_LT,O14)) | I14: =IF(O14="","",H14+SimDelay) | J14: =IF(O14="","",IF(I14>G14,"Stockout","Covered")) | K14: =IF(O14="","",ROUNDUP(MAX(0,I14-G14)*E14,0)) | L14: =IF(O14="","",K14*INDEX(P_Cost,O14)*Markup) | M14: =IF(O14="","",ROUNDUP(E14*SimDelay,0)) | N14: =IF(O14="","",M14*INDEX(P_Cost,O14)) | O14: =IFERROR(MATCH(A14,P_SimRow,0),"")
A15: 3 | B15: =IF(O15="","",INDEX(P_SKU,O15)) | C15: =IF(O15="","",INDEX(P_Name,O15)) | D15: =IF(O15="","",INDEX(P_ABC,O15)) | E15: =IF(O15="","",INDEX(P_Demand,O15)) | F15: =IF(O15="","",INDEX(P_Pos,O15)) | G15: =IF(O15="","",IFERROR(F15/E15,999)) | H15: =IF(O15="","",INDEX(P_LT,O15)) | I15: =IF(O15="","",H15+SimDelay) | J15: =IF(O15="","",IF(I15>G15,"Stockout","Covered")) | K15: =IF(O15="","",ROUNDUP(MAX(0,I15-G15)*E15,0)) | L15: =IF(O15="","",K15*INDEX(P_Cost,O15)*Markup) | M15: =IF(O15="","",ROUNDUP(E15*SimDelay,0)) | N15: =IF(O15="","",M15*INDEX(P_Cost,O15)) | O15: =IFERROR(MATCH(A15,P_SimRow,0),"")
A16: 4 | B16: =IF(O16="","",INDEX(P_SKU,O16)) | C16: =IF(O16="","",INDEX(P_Name,O16)) | D16: =IF(O16="","",INDEX(P_ABC,O16)) | E16: =IF(O16="","",INDEX(P_Demand,O16)) | F16: =IF(O16="","",INDEX(P_Pos,O16)) | G16: =IF(O16="","",IFERROR(F16/E16,999)) | H16: =IF(O16="","",INDEX(P_LT,O16)) | I16: =IF(O16="","",H16+SimDelay) | J16: =IF(O16="","",IF(I16>G16,"Stockout","Covered")) | K16: =IF(O16="","",ROUNDUP(MAX(0,I16-G16)*E16,0)) | L16: =IF(O16="","",K16*INDEX(P_Cost,O16)*Markup) | M16: =IF(O16="","",ROUNDUP(E16*SimDelay,0)) | N16: =IF(O16="","",M16*INDEX(P_Cost,O16)) | O16: =IFERROR(MATCH(A16,P_SimRow,0),"")
A17: 5 | B17: =IF(O17="","",INDEX(P_SKU,O17)) | C17: =IF(O17="","",INDEX(P_Name,O17)) | D17: =IF(O17="","",INDEX(P_ABC,O17)) | E17: =IF(O17="","",INDEX(P_Demand,O17)) | F17: =IF(O17="","",INDEX(P_Pos,O17)) | G17: =IF(O17="","",IFERROR(F17/E17,999)) | H17: =IF(O17="","",INDEX(P_LT,O17)) | I17: =IF(O17="","",H17+SimDelay) | J17: =IF(O17="","",IF(I17>G17,"Stockout","Covered")) | K17: =IF(O17="","",ROUNDUP(MAX(0,I17-G17)*E17,0)) | L17: =IF(O17="","",K17*INDEX(P_Cost,O17)*Markup) | M17: =IF(O17="","",ROUNDUP(E17*SimDelay,0)) | N17: =IF(O17="","",M17*INDEX(P_Cost,O17)) | O17: =IFERROR(MATCH(A17,P_SimRow,0),"")
A18: 6 | B18: =IF(O18="","",INDEX(P_SKU,O18)) | C18: =IF(O18="","",INDEX(P_Name,O18)) | D18: =IF(O18="","",INDEX(P_ABC,O18)) | E18: =IF(O18="","",INDEX(P_Demand,O18)) | F18: =IF(O18="","",INDEX(P_Pos,O18)) | G18: =IF(O18="","",IFERROR(F18/E18,999)) | H18: =IF(O18="","",INDEX(P_LT,O18)) | I18: =IF(O18="","",H18+SimDelay) | J18: =IF(O18="","",IF(I18>G18,"Stockout","Covered")) | K18: =IF(O18="","",ROUNDUP(MAX(0,I18-G18)*E18,0)) | L18: =IF(O18="","",K18*INDEX(P_Cost,O18)*Markup) | M18: =IF(O18="","",ROUNDUP(E18*SimDelay,0)) | N18: =IF(O18="","",M18*INDEX(P_Cost,O18)) | O18: =IFERROR(MATCH(A18,P_SimRow,0),"")
A19: 7 | B19: =IF(O19="","",INDEX(P_SKU,O19)) | C19: =IF(O19="","",INDEX(P_Name,O19)) | D19: =IF(O19="","",INDEX(P_ABC,O19)) | E19: =IF(O19="","",INDEX(P_Demand,O19)) | F19: =IF(O19="","",INDEX(P_Pos,O19)) | G19: =IF(O19="","",IFERROR(F19/E19,999)) | H19: =IF(O19="","",INDEX(P_LT,O19)) | I19: =IF(O19="","",H19+SimDelay) | J19: =IF(O19="","",IF(I19>G19,"Stockout","Covered")) | K19: =IF(O19="","",ROUNDUP(MAX(0,I19-G19)*E19,0)) | L19: =IF(O19="","",K19*INDEX(P_Cost,O19)*Markup) | M19: =IF(O19="","",ROUNDUP(E19*SimDelay,0)) | N19: =IF(O19="","",M19*INDEX(P_Cost,O19)) | O19: =IFERROR(MATCH(A19,P_SimRow,0),"")
A20: 8 | B20: =IF(O20="","",INDEX(P_SKU,O20)) | C20: =IF(O20="","",INDEX(P_Name,O20)) | D20: =IF(O20="","",INDEX(P_ABC,O20)) | E20: =IF(O20="","",INDEX(P_Demand,O20)) | F20: =IF(O20="","",INDEX(P_Pos,O20)) | G20: =IF(O20="","",IFERROR(F20/E20,999)) | H20: =IF(O20="","",INDEX(P_LT,O20)) | I20: =IF(O20="","",H20+SimDelay) | J20: =IF(O20="","",IF(I20>G20,"Stockout","Covered")) | K20: =IF(O20="","",ROUNDUP(MAX(0,I20-G20)*E20,0)) | L20: =IF(O20="","",K20*INDEX(P_Cost,O20)*Markup) | M20: =IF(O20="","",ROUNDUP(E20*SimDelay,0)) | N20: =IF(O20="","",M20*INDEX(P_Cost,O20)) | O20: =IFERROR(MATCH(A20,P_SimRow,0),"")
